Workbook

Sheet 概要
A1: システムアーキテクト午前II 過去問分析
A2: 午前II 10回分(2015〜2019年・2021〜2025年)の問題冊子を文字認識で取り込んだ分析です。
A4: 項目 | B4: 値 | C4: 説明
A5: 分析した問題数 | B5: =COUNT(問題一覧!$B$5:$B$254) -> 250 | C5: 午前II全回の合計
A6: 試験回数 | B6: 10 | C6: 実施された回の数(入力値: 2020年は試験がないため除く)
A7: 同じ問題が複数回出た問題数 | B7: =COUNT(問題一覧!$E$5:$E$254) -> 96 | C7: 他の回にも同一問題がある問題
A8: 同一問題の組の数 | B8: =COUNTA(再出題一覧!A5:A49) -> 45 | C8: 同じ設問が繰り返された組
A9: 重複を除いた問題数 | B9: =B5-B7+B8 -> 199 | C9: 同一問題を1つと数えた場合
A10: 再出題された問題の割合 | B10: =B7/B5 -> 0.384 | C10: 全問題に占める割合
A11: 翌回に再出題された組数 | B11: =再出題の間隔!B5 -> 0 | C11: 連続する2回で同一問題が出た数(0)
A12: 2回後に再出題された組数 | B12: =再出題の間隔!B6 -> 20 | C12: 最も多い間隔
A14: 読み方
A15: ・同じ問題が戻ってくるのは翌回ではなく、2回後以降です。直前の回の問題は同一問題としては出ない傾向でした。
A16: ・同テーマの別設問は直前の回でも出ています。直前の回だけでなく、少し前の回まで過去問を広げるほうが効きます。
A17: ・分類は試験要綱の「試験区分別出題分野一覧表」の中分類（SAの出題範囲10分野）です。システム開発技術とセキュリティの2分野で毎回約15問を占めます。
A18: ・中分類別の出題数は「分野別」、次回の予想は「出題予想」、覚える用語は「用語一覧」(優先度A→B→C)にまとめています。
A19: 注意
A20: ・問題冊子は画像のPDFだったため、文字認識の誤りで取りこぼした再出題がある可能性があります。
A21: ・設問文と選択肢がほぼ一致するものを同一問題、同じ用語分類の別設問を同テーマとしました。各問の中分類はIPAが公表していないため、出題内容から判断して付けています（要件定義はシステム開発技術とシステム企画の境界が分かれやすい）。
A22: ・回別内訳・再出題の間隔・回どうしの重なり・過去問のカバー数は類似度判定の結果を貼り付けた固定値です。
A23: ・応用情報技術者試験の問題との照合は含まれていません。

Sheet 問題一覧
A1: 全250問の分類(午前II 10回分)
A2: 年度は問題冊子の年。再出題グループは、同じ設問が複数回出た組の番号(空欄は単発または同テーマのみ)。
A4: 年 | B4: 問番号 | C4: 中分類（試験要綱） | D4: 用語・テーマ | E4: 再出題グループ
A5: 2015 | B5: 1 | C5: 12 システム開発技術 | D5: JIS X 0160(SLCP)
A6: 2015 | B6: 2 | C6: 12 システム開発技術 | D6: UML
A7: 2015 | B7: 3 | C7: 12 システム開発技術 | D7: ユースケース
A8: 2015 | B8: 4 | C8: 12 システム開発技術 | D8: 設計原則(SOLID) | E8: 6
A9: 2015 | B9: 5 | C9: 12 システム開発技術 | D9: デザインパターン/アーキテクチャパターン | E9: 7
A10: 2015 | B10: 6 | C10: 4 システム構成要素 | D10: MapReduce | E10: 8
A11: 2015 | B11: 7 | C11: 12 システム開発技術 | D11: デザインパターン/アーキテクチャパターン | E11: 9
A12: 2015 | B12: 8 | C12: 12 システム開発技術 | D12: テスト技法(ブラックボックス/網羅) | E12: 10
A13: 2015 | B13: 9 | C13: 12 システム開発技術 | D13: 検査費用の計算 | E13: 11
A14: 2015 | B14: 10 | C14: 12 システム開発技術 | D14: テスト技法(ブラックボックス/網羅)
A15: 2015 | B15: 11 | C15: 12 システム開発技術 | D15: 共通フレーム2013
A16: 2015 | B16: 12 | C16: 12 システム開発技術 | D16: カークパトリックモデル | E16: 12
A17: 2015 | B17: 13 | C17: 13 ソフトウェア開発管理技術 | D17: 再利用(ドメイン工学) | E17: 13
A18: 2015 | B18: 14 | C18: 18 システム企画 | D18: BABOK/要求の分類
A19: 2015 | B19: 15 | C19: 18 システム企画 | D19: 共通フレーム2013
A20: 2015 | B20: 16 | C20: 18 システム企画 | D20: 契約形態(請負/準委任/ラボ/実費償還) | E20: 0
A21: 2015 | B21: 17 | C21: 4 システム構成要素 | D21: BCP・RTO
A22: 2015 | B22: 18 | C22: 3 コンピュータ構成要素 | D22: 仮想記憶・割込み
A23: 2015 | B23: 19 | C23: 4 システム構成要素 | D23: フェールセーフ/フェールソフト/フォールトトレランス | E23: 14
A24: 2015 | B24: 20 | C24: 3 コンピュータ構成要素 | D24: マルチプロセッサ(アムダールの法則)
A25: 2015 | B25: 21 | C25: 9 データベース | D25: OLAP
A26: 2015 | B26: 22 | C26: 10 ネットワーク | D26: LAN(CSMA/スイッチングハブ)
A27: 2015 | B27: 23 | C27: 11 セキュリティ | D27: リスク分析・ガバナンス
A28: 2015 | B28: 24 | C28: 11 セキュリティ | D28: 電子署名・PKI・TPM
A29: 2015 | B29: 25 | C29: 11 セキュリティ | D29: Web脆弱性対策(XSS/WAF)
A30: 2016 | B30: 1 | C30: 12 システム開発技術 | D30: JIS X 0160(SLCP)
A31: 2016 | B31: 2 | C31: 12 システム開発技術 | D31: 共通フレーム2013
A32: 2016 | B32: 3 | C32: 12 システム開発技術 | D32: DFD/構造化技法
A33: 2016 | B33: 4 | C33: 12 システム開発技術 | D33: ペトリネット(同期の要求モデル) | E33: 15
A34: 2016 | B34: 5 | C34: 9 データベース | D34: データモデル設計
A35: 2016 | B35: 6 | C35: 12 システム開発技術 | D35: DFD/構造化技法
A36: 2016 | B36: 7 | C36: 12 システム開発技術 | D36: 結合度・モジュール分割
A37: 2016 | B37: 8 | C37: 12 システム開発技術 | D37: JIS X 25010(SQuaRE品質)
A38: 2016 | B38: 9 | C38: 12 システム開発技術 | D38: コーディング規約(MISRA C)
A39: 2016 | B39: 10 | C39: 12 システム開発技術 | D39: テスト技法(ブラックボックス/網羅)
A40: 2016 | B40: 11 | C40: 12 システム開発技術 | D40: 品質予測(バグ管理図/エラー埋込み)
A41: 2016 | B41: 12 | C41: 12 システム開発技術 | D41: 保守
...

Sheet 再出題一覧
A1: 再出題された45組
A2: 同じ設問が複数回出た組。出題回と問番号は問題冊子と照らして確認できます。
A4: グループ | B4: 問題の内容 | C4: 用語・テーマ | D4: 中分類 | E4: 出題回数 | F4: 出題された回と問番号
A5: 0 | B5: 実費償還型契約の説明 | C5: 契約形態(請負/準委任/ラボ/実費償還) | D5: 18 システム企画 | E5: =COUNTIF(問題一覧!$E$5:$E$254,A5) -> 3 | F5: 2015年問16 / 2017年問16 / 2023年問15
A6: 2 | B6: 電話機とPBXをIPネットワークに統合する構成 | C6: IP電話(VoIP) | D6: 10 ネットワーク | E6: =COUNTIF(問題一覧!$E$5:$E$254,A6) -> 3 | F6: 2017年問22 / 2019年問22 / 2022年問25
A7: 3 | B7: 署名済みソフトの発行元の確認(電子署名) | C7: 電子署名・PKI・TPM | D7: 11 セキュリティ | E7: =COUNTIF(問題一覧!$E$5:$E$254,A7) -> 3 | F7: 2017年問23 / 2019年問23 / 2024年問17
A8: 4 | B8: スパム対策: サブミッションポート587の導入目的 | C8: メールセキュリティ(OP25B/SPF/ベイジアン) | D8: 11 セキュリティ | E8: =COUNTIF(問題一覧!$E$5:$E$254,A8) -> 3 | F8: 2017年問25 / 2021年問20 / 2025年問19
A9: 1 | B9: GoFのデザインパターンの説明 | C9: デザインパターン/アーキテクチャパターン | D9: 12 システム開発技術 | E9: =COUNTIF(問題一覧!$E$5:$E$254,A9) -> 3 | F9: 2017年問5 / 2019年問3 / 2022年問2
A10: 5 | B10: WTO政府調達協定の説明 | C10: WTO政府調達協定 | D10: 18 システム企画 | E10: =COUNTIF(問題一覧!$E$5:$E$254,A10) -> 3 | F10: 2018年問15 / 2021年問15 / 2023年問14
A11: 12 | B11: カークパトリックモデル(教育効果の測定) | C11: カークパトリックモデル | D11: 12 システム開発技術 | E11: =COUNTIF(問題一覧!$E$5:$E$254,A11) -> 2 | F11: 2015年問12 / 2025年問10
A12: 13 | B12: 特定分野の業務知識・再利用部品の体系化 | C12: 再利用(ドメイン工学) | D12: 13 ソフトウェア開発管理技術 | E12: =COUNTIF(問題一覧!$E$5:$E$254,A12) -> 2 | F12: 2015年問13 / 2017年問13
A13: 14 | B13: フォールトトレランスの説明 | C13: フェールセーフ/フェールソフト/フォールトトレランス | D13: 4 システム構成要素 | E13: =COUNTIF(問題一覧!$E$5:$E$254,A13) -> 2 | F13: 2015年問19 / 2021年問23
A14: 6 | B14: 設計原則: 開放閉鎖原則 | C14: 設計原則(SOLID) | D14: 12 システム開発技術 | E14: =COUNTIF(問題一覧!$E$5:$E$254,A14) -> 2 | F14: 2015年問4 / 2025年問2
A15: 7 | B15: ストラテジパターンによる帳票出力クラスの設計 | C15: デザインパターン/アーキテクチャパターン | D15: 12 システム開発技術 | E15: =COUNTIF(問題一覧!$E$5:$E$254,A15) -> 2 | F15: 2015年問5 / 2022年問5
A16: 8 | B16: 中間キーと値の組を扱う並列処理(MapReduce) | C16: MapReduce | D16: 4 システム構成要素 | E16: =COUNTIF(問題一覧!$E$5:$E$254,A16) -> 2 | F16: 2015年問6 / 2025年問4
... A49: 44 | B49: CSMA/CD方式LANとスイッチングハブ | C49: LAN(CSMA/スイッチングハブ) | D49: 10 ネットワーク | E49: =COUNTIF(問題一覧!$E$5:$E$254,A49) -> 2 | F49: 2023年問25 / 2025年問25

Sheet 分野別
A1: 中分類別の問題数と回別の出題数
A2: 試験要綱「試験区分別出題分野一覧表」の中分類（SAの出題範囲10分野）で分類。問題一覧からの集計(数式)。
A4: 中分類 | B4: 問題数 | C4: 再出題あり | D4: それ以外 | E4: 2015 | F4: 2016 | G4: 2017 | H4: 2018 | I4: 2019 | J4: 2021 | K4: 2022 | L4: 2023 | M4: 2024 | N4: 2025
A5: 12 システム開発技術 | B5: =COUNTIF(問題一覧!$C$5:$C$254,A5) -> 105 | C5: =COUNTIFS(問題一覧!$C$5:$C$254,A5,問題一覧!$E$5:$E$254,">=0") -> 48 | D5: =B5-C5 -> 57 | E5: =COUNTIFS(問題一覧!$C$5:$C$254,$A5,問題一覧!$A$5:$A$254,2015) -> 11 | F5: =COUNTIFS(問題一覧!$C$5:$C$254,$A5,問題一覧!$A$5:$A$254,2016) -> 12 | G5: =COUNTIFS(問題一覧!$C$5:$C$254,$A5,問題一覧!$A$5:$A$254,2017) -> 9 | H5: =COUNTIFS(問題一覧!$C$5:$C$254,$A5,問題一覧!$A$5:$A$254,2018) -> 10 | I5: =COUNTIFS(問題一覧!$C$5:$C$254,$A5,問題一覧!$A$5:$A$254,2019) -> 12 | J5: =COUNTIFS(問題一覧!$C$5:$C$254,$A5,問題一覧!$A$5:$A$254,2021) -> 12 | K5: =COUNTIFS(問題一覧!$C$5:$C$254,$A5,問題一覧!$A$5:$A$254,2022) -> 10 | L5: =COUNTIFS(問題一覧!$C$5:$C$254,$A5,問題一覧!$A$5:$A$254,2023) -> 9 | M5: =COUNTIFS(問題一覧!$C$5:$C$254,$A5,問題一覧!$A$5:$A$254,2024) -> 10 | N5: =COUNTIFS(問題一覧!$C$5:$C$254,$A5,問題一覧!$A$5:$A$254,2025) -> 10
A6: 11 セキュリティ | B6: =COUNTIF(問題一覧!$C$5:$C$254,A6) -> 40 | C6: =COUNTIFS(問題一覧!$C$5:$C$254,A6,問題一覧!$E$5:$E$254,">=0") -> 16 | D6: =B6-C6 -> 24 | E6: =COUNTIFS(問題一覧!$C$5:$C$254,$A6,問題一覧!$A$5:$A$254,2015) -> 3 | F6: =COUNTIFS(問題一覧!$C$5:$C$254,$A6,問題一覧!$A$5:$A$254,2016) -> 4 | G6: =COUNTIFS(問題一覧!$C$5:$C$254,$A6,問題一覧!$A$5:$A$254,2017) -> 3 | H6: =COUNTIFS(問題一覧!$C$5:$C$254,$A6,問題一覧!$A$5:$A$254,2018) -> 3 | I6: =COUNTIFS(問題一覧!$C$5:$C$254,$A6,問題一覧!$A$5:$A$254,2019) -> 3 | J6: =COUNTIFS(問題一覧!$C$5:$C$254,$A6,問題一覧!$A$5:$A$254,2021) -> 4 | K6: =COUNTIFS(問題一覧!$C$5:$C$254,$A6,問題一覧!$A$5:$A$254,2022) -> 5 | L6: =COUNTIFS(問題一覧!$C$5:$C$254,$A6,問題一覧!$A$5:$A$254,2023) -> 5 | M6: =COUNTIFS(問題一覧!$C$5:$C$254,$A6,問題一覧!$A$5:$A$254,2024) -> 5 | N6: =COUNTIFS(問題一覧!$C$5:$C$254,$A6,問題一覧!$A$5:$A$254,2025) -> 5
A7: 4 システム構成要素 | B7: =COUNTIF(問題一覧!$C$5:$C$254,A7) -> 23 | C7: =COUNTIFS(問題一覧!$C$5:$C$254,A7,問題一覧!$E$5:$E$254,">=0") -> 8 | D7: =B7-C7 -> 15 | E7: =COUNTIFS(問題一覧!$C$5:$C$254,$A7,問題一覧!$A$5:$A$254,2015) -> 3 | F7: =COUNTIFS(問題一覧!$C$5:$C$254,$A7,問題一覧!$A$5:$A$254,2016) -> 4 | G7: =COUNTIFS(問題一覧!$C$5:$C$254,$A7,問題一覧!$A$5:$A$254,2017) -> 2 | H7: =COUNTIFS(問題一覧!$C$5:$C$254,$A7,問題一覧!$A$5:$A$254,2018) -> 3 | I7: =COUNTIFS(問題一覧!$C$5:$C$254,$A7,問題一覧!$A$5:$A$254,2019) -> 1 | J7: =COUNTIFS(問題一覧!$C$5:$C$254,$A7,問題一覧!$A$5:$A$254,2021) -> 2 | K7: =COUNTIFS(問題一覧!$C$5:$C$254,$A7,問題一覧!$A$5:$A$254,2022) -> 1 | L7: =COUNTIFS(問題一覧!$C$5:$C$254,$A7,問題一覧!$A$5:$A$254,2023) -> 2 | M7: =COUNTIFS(問題一覧!$C$5:$C$254,$A7,問題一覧!$A$5:$A$254,2024) -> 2 | N7: =COUNTIFS(問題一覧!$C$5:$C$254,$A7,問題一覧!$A$5:$A$254,2025) -> 3
A8: 18 システム企画 | B8: =COUNTIF(問題一覧!$C$5:$C$254,A8) -> 19 | C8: =COUNTIFS(問題一覧!$C$5:$C$254,A8,問題一覧!$E$5:$E$254,">=0") -> 10 | D8: =B8-C8 -> 9 | E8: =COUNTIFS(問題一覧!$C$5:$C$254,$A8,問題一覧!$A$5:$A$254,2015) -> 3 | F8: =COUNTIFS(問題一覧!$C$5:$C$254,$A8,問題一覧!$A$5:$A$254,2016) -> 2 | G8: =COUNTIFS(問題一覧!$C$5:$C$254,$A8,問題一覧!$A$5:$A$254,2017) -> 2 | H8: =COUNTIFS(問題一覧!$C$5:$C$254,$A8,問題一覧!$A$5:$A$254,2018) -> 3 | I8: =COUNTIFS(問題一覧!$C$5:$C$254,$A8,問題一覧!$A$5:$A$254,2019) -> 2 | J8: =COUNTIFS(問題一覧!$C$5:$C$254,$A8,問題一覧!$A$5:$A$254,2021) -> 1 | K8: =COUNTIFS(問題一覧!$C$5:$C$254,$A8,問題一覧!$A$5:$A$254,2022) -> 1 | L8: =COUNTIFS(問題一覧!$C$5:$C$254,$A8,問題一覧!$A$5:$A$254,2023) -> 2 | M8: =COUNTIFS(問題一覧!$C$5:$C$254,$A8,問題一覧!$A$5:$A$254,2024) -> 1 | N8: =COUNTIFS(問題一覧!$C$5:$C$254,$A8,問題一覧!$A$5:$A$254,2025) -> 2
A9: 9 データベース | B9: =COUNTIF(問題一覧!$C$5:$C$254,A9) -> 14 | C9: =COUNTIFS(問題一覧!$C$5:$C$254,A9,問題一覧!$E$5:$E$254,">=0") -> 2 | D9: =B9-C9 -> 12 | E9: =COUNTIFS(問題一覧!$C$5:$C$254,$A9,問題一覧!$A$5:$A$254,2015) -> 1 | F9: =COUNTIFS(問題一覧!$C$5:$C$254,$A9,問題一覧!$A$5:$A$254,2016) -> 2 | G9: =COUNTIFS(問題一覧!$C$5:$C$254,$A9,問題一覧!$A$5:$A$254,2017) -> 1 | H9: =COUNTIFS(問題一覧!$C$5:$C$254,$A9,問題一覧!$A$5:$A$254,2018) -> 1 | I9: =COUNTIFS(問題一覧!$C$5:$C$254,$A9,問題一覧!$A$5:$A$254,2019) -> 1 | J9: =COUNTIFS(問題一覧!$C$5:$C$254,$A9,問題一覧!$A$5:$A$254,2021) -> 1 | K9: =COUNTIFS(問題一覧!$C$5:$C$254,$A9,問題一覧!$A$5:$A$254,2022) -> 3 | L9: =COUNTIFS(問題一覧!$C$5:$C$254,$A9,問題一覧!$A$5:$A$254,2023) -> 1 | M9: =COUNTIFS(問題一覧!$C$5:$C$254,$A9,問題一覧!$A$5:$A$254,2024) -> 2 | N9: =COUNTIFS(問題一覧!$C$5:$C$254,$A9,問題一覧!$A$5:$A$254,2025) -> 1
A10: 13 ソフトウェア開発管理技術 | B10: =COUNTIF(問題一覧!$C$5:$C$254,A10) -> 14 | C10: =COUNTIFS(問題一覧!$C$5:$C$254,A10,問題一覧!$E$5:$E$254,">=0") -> 6 | D10: =B10-C10 -> 8 | E10: =COUNTIFS(問題一覧!$C$5:$C$254,$A10,問題一覧!$A$5:$A$254,2015) -> 1 | F10: =COUNTIFS(問題一覧!$C$5:$C$254,$A10,問題一覧!$A$5:$A$254,2016) -> 0 | G10: =COUNTIFS(問題一覧!$C$5:$C$254,$A10,問題一覧!$A$5:$A$254,2017) -> 3 | H10: =COUNTIFS(問題一覧!$C$5:$C$254,$A10,問題一覧!$A$5:$A$254,2018) -> 2 | I10: =COUNTIFS(問題一覧!$C$5:$C$254,$A10,問題一覧!$A$5:$A$254,2019) -> 1 | J10: =COUNTIFS(問題一覧!$C$5:$C$254,$A10,問題一覧!$A$5:$A$254,2021) -> 1 | K10: =COUNTIFS(問題一覧!$C$5:$C$254,$A10,問題一覧!$A$5:$A$254,2022) -> 2 | L10: =COUNTIFS(問題一覧!$C$5:$C$254,$A10,問題一覧!$A$5:$A$254,2023) -> 2 | M10: =COUNTIFS(問題一覧!$C$5:$C$254,$A10,問題一覧!$A$5:$A$254,2024) -> 2 | N10: =COUNTIFS(問題一覧!$C$5:$C$254,$A10,問題一覧!$A$5:$A$254,2025) -> 0
A11: 3 コンピュータ構成要素 | B11: =COUNTIF(問題一覧!$C$5:$C$254,A11) -> 12 | C11: =COUNTIFS(問題一覧!$C$5:$C$254,A11,問題一覧!$E$5:$E$254,">=0") -> 0 | D11: =B11-C11 -> 12 | E11: =COUNTIFS(問題一覧!$C$5:$C$254,$A11,問題一覧!$A$5:$A$254,2015) -> 2 | F11: =COUNTIFS(問題一覧!$C$5:$C$254,$A11,問題一覧!$A$5:$A$254,2016) -> 0 | G11: =COUNTIFS(問題一覧!$C$5:$C$254,$A11,問題一覧!$A$5:$A$254,2017) -> 2 | H11: =COUNTIFS(問題一覧!$C$5:$C$254,$A11,問題一覧!$A$5:$A$254,2018) -> 1 | I11: =COUNTIFS(問題一覧!$C$5:$C$254,$A11,問題一覧!$A$5:$A$254,2019) -> 2 | J11: =COUNTIFS(問題一覧!$C$5:$C$254,$A11,問題一覧!$A$5:$A$254,2021) -> 1 | K11: =COUNTIFS(問題一覧!$C$5:$C$254,$A11,問題一覧!$A$5:$A$254,2022) -> 1 | L11: =COUNTIFS(問題一覧!$C$5:$C$254,$A11,問題一覧!$A$5:$A$254,2023) -> 1 | M11: =COUNTIFS(問題一覧!$C$5:$C$254,$A11,問題一覧!$A$5:$A$254,2024) -> 1 | N11: =COUNTIFS(問題一覧!$C$5:$C$254,$A11,問題一覧!$A$5:$A$254,2025) -> 1
A12: 17 システム戦略 | B12: =COUNTIF(問題一覧!$C$5:$C$254,A12) -> 12 | C12: =COUNTIFS(問題一覧!$C$5:$C$254,A12,問題一覧!$E$5:$E$254,">=0") -> 1 | D12: =B12-C12 -> 11 | E12: =COUNTIFS(問題一覧!$C$5:$C$254,$A12,問題一覧!$A$5:$A$254,2015) -> 0 | F12: =COUNTIFS(問題一覧!$C$5:$C$254,$A12,問題一覧!$A$5:$A$254,2016) -> 1 | G12: =COUNTIFS(問題一覧!$C$5:$C$254,$A12,問題一覧!$A$5:$A$254,2017) -> 2 | H12: =COUNTIFS(問題一覧!$C$5:$C$254,$A12,問題一覧!$A$5:$A$254,2018) -> 2 | I12: =COUNTIFS(問題一覧!$C$5:$C$254,$A12,問題一覧!$A$5:$A$254,2019) -> 1 | J12: =COUNTIFS(問題一覧!$C$5:$C$254,$A12,問題一覧!$A$5:$A$254,2021) -> 2 | K12: =COUNTIFS(問題一覧!$C$5:$C$254,$A12,問題一覧!$A$5:$A$254,2022) -> 1 | L12: =COUNTIFS(問題一覧!$C$5:$C$254,$A12,問題一覧!$A$5:$A$254,2023) -> 2 | M12: =COUNTIFS(問題一覧!$C$5:$C$254,$A12,問題一覧!$A$5:$A$254,2024) -> 0 | N12: =COUNTIFS(問題一覧!$C$5:$C$254,$A12,問題一覧!$A$5:$A$254,2025) -> 1
A13: 10 ネットワーク | B13: =COUNTIF(問題一覧!$C$5:$C$254,A13) -> 8 | C13: =COUNTIFS(問題一覧!$C$5:$C$254,A13,問題一覧!$E$5:$E$254,">=0") -> 5 | D13: =B13-C13 -> 3 | E13: =COUNTIFS(問題一覧!$C$5:$C$254,$A13,問題一覧!$A$5:$A$254,2015) -> 1 | F13: =COUNTIFS(問題一覧!$C$5:$C$254,$A13,問題一覧!$A$5:$A$254,2016) -> 0 | G13: =COUNTIFS(問題一覧!$C$5:$C$254,$A13,問題一覧!$A$5:$A$254,2017) -> 1 | H13: =COUNTIFS(問題一覧!$C$5:$C$254,$A13,問題一覧!$A$5:$A$254,2018) -> 0 | I13: =COUNTIFS(問題一覧!$C$5:$C$254,$A13,問題一覧!$A$5:$A$254,2019) -> 1 | J13: =COUNTIFS(問題一覧!$C$5:$C$254,$A13,問題一覧!$A$5:$A$254,2021) -> 1 | K13: =COUNTIFS(問題一覧!$C$5:$C$254,$A13,問題一覧!$A$5:$A$254,2022) -> 1 | L13: =COUNTIFS(問題一覧!$C$5:$C$254,$A13,問題一覧!$A$5:$A$254,2023) -> 1 | M13: =COUNTIFS(問題一覧!$C$5:$C$254,$A13,問題一覧!$A$5:$A$254,2024) -> 1 | N13: =COUNTIFS(問題一覧!$C$5:$C$254,$A13,問題一覧!$A$5:$A$254,2025) -> 1
A14: 7 ユーザーインタフェース | B14: =COUNTIF(問題一覧!$C$5:$C$254,A14) -> 3 | C14: =COUNTIFS(問題一覧!$C$5:$C$254,A14,問題一覧!$E$5:$E$254,">=0") -> 0 | D14: =B14-C14 -> 3 | E14: =COUNTIFS(問題一覧!$C$5:$C$254,$A14,問題一覧!$A$5:$A$254,2015) -> 0 | F14: =COUNTIFS(問題一覧!$C$5:$C$254,$A14,問題一覧!$A$5:$A$254,2016) -> 0 | G14: =COUNTIFS(問題一覧!$C$5:$C$254,$A14,問題一覧!$A$5:$A$254,2017) -> 0 | H14: =COUNTIFS(問題一覧!$C$5:$C$254,$A14,問題一覧!$A$5:$A$254,2018) -> 0 | I14: =COUNTIFS(問題一覧!$C$5:$C$254,$A14,問題一覧!$A$5:$A$254,2019) -> 1 | J14: =COUNTIFS(問題一覧!$C$5:$C$254,$A14,問題一覧!$A$5:$A$254,2021) -> 0 | K14: =COUNTIFS(問題一覧!$C$5:$C$254,$A14,問題一覧!$A$5:$A$254,2022) -> 0 | L14: =COUNTIFS(問題一覧!$C$5:$C$254,$A14,問題一覧!$A$5:$A$254,2023) -> 0 | M14: =COUNTIFS(問題一覧!$C$5:$C$254,$A14,問題一覧!$A$5:$A$254,2024) -> 1 | N14: =COUNTIFS(問題一覧!$C$5:$C$254,$A14,問題一覧!$A$5:$A$254,2025) -> 1
A15: 合計 | B15: =SUM(B5:B14) -> 250 | C15: =SUM(C5:C14) -> 96 | D15: =SUM(D5:D14) -> 154 | E15: =SUM(E5:E14) -> 25 | F15: =SUM(F5:F14) -> 25 | G15: =SUM(G5:G14) -> 25 | H15: =SUM(H5:H14) -> 25 | I15: =SUM(I5:I14) -> 25 | ... N15: =SUM(N5:N14) -> 25

Sheet 出題予想
A1: 中分類別の出題数の予想（25問）
A2: 平均・最小・最大は分野別シートからの数式。予想問数(青字)は直近5回の傾向と範囲の変更を踏まえた入力値で、合計25問になるよう調整。◎は試験要綱の重点分野。
A4: 中分類 | B4: 要綱 | C4: 直近5回平均 | D4: 直近5回最小 | E4: 直近5回最大 | F4: 10回平均 | G4: 予想問数
A5: 12 システム開発技術 | B5: ◎ | C5: =AVERAGE(INDEX(分野別!$J$5:$N$14,MATCH(A5,分野別!$A$5:$A$14,0),0)) -> 10.2 | D5: =MIN(INDEX(分野別!$J$5:$N$14,MATCH(A5,分野別!$A$5:$A$14,0),0)) -> 9 | E5: =MAX(INDEX(分野別!$J$5:$N$14,MATCH(A5,分野別!$A$5:$A$14,0),0)) -> 12 | F5: =AVERAGE(INDEX(分野別!$E$5:$N$14,MATCH(A5,分野別!$A$5:$A$14,0),0)) -> 10.5 | G5: 10
A6: 11 セキュリティ | B6: ◎ | C6: =AVERAGE(INDEX(分野別!$J$5:$N$14,MATCH(A6,分野別!$A$5:$A$14,0),0)) -> 4.8 | D6: =MIN(INDEX(分野別!$J$5:$N$14,MATCH(A6,分野別!$A$5:$A$14,0),0)) -> 4 | E6: =MAX(INDEX(分野別!$J$5:$N$14,MATCH(A6,分野別!$A$5:$A$14,0),0)) -> 5 | F6: =AVERAGE(INDEX(分野別!$E$5:$N$14,MATCH(A6,分野別!$A$5:$A$14,0),0)) -> 4 | G6: 5
A7: 4 システム構成要素 | B7: ○ | C7: =AVERAGE(INDEX(分野別!$J$5:$N$14,MATCH(A7,分野別!$A$5:$A$14,0),0)) -> 2 | D7: =MIN(INDEX(分野別!$J$5:$N$14,MATCH(A7,分野別!$A$5:$A$14,0),0)) -> 1 | E7: =MAX(INDEX(分野別!$J$5:$N$14,MATCH(A7,分野別!$A$5:$A$14,0),0)) -> 3 | F7: =AVERAGE(INDEX(分野別!$E$5:$N$14,MATCH(A7,分野別!$A$5:$A$14,0),0)) -> 2.3 | G7: 2
A8: 18 システム企画 | B8: ◎ | C8: =AVERAGE(INDEX(分野別!$J$5:$N$14,MATCH(A8,分野別!$A$5:$A$14,0),0)) -> 1.4 | D8: =MIN(INDEX(分野別!$J$5:$N$14,MATCH(A8,分野別!$A$5:$A$14,0),0)) -> 1 | E8: =MAX(INDEX(分野別!$J$5:$N$14,MATCH(A8,分野別!$A$5:$A$14,0),0)) -> 2 | F8: =AVERAGE(INDEX(分野別!$E$5:$N$14,MATCH(A8,分野別!$A$5:$A$14,0),0)) -> 1.9 | G8: 2
A9: 9 データベース | B9: ○ | C9: =AVERAGE(INDEX(分野別!$J$5:$N$14,MATCH(A9,分野別!$A$5:$A$14,0),0)) -> 1.6 | D9: =MIN(INDEX(分野別!$J$5:$N$14,MATCH(A9,分野別!$A$5:$A$14,0),0)) -> 1 | E9: =MAX(INDEX(分野別!$J$5:$N$14,MATCH(A9,分野別!$A$5:$A$14,0),0)) -> 3 | F9: =AVERAGE(INDEX(分野別!$E$5:$N$14,MATCH(A9,分野別!$A$5:$A$14,0),0)) -> 1.4 | G9: 1
A10: 13 ソフトウェア開発管理技術 | B10: ○ | C10: =AVERAGE(INDEX(分野別!$J$5:$N$14,MATCH(A10,分野別!$A$5:$A$14,0),0)) -> 1.4 | D10: =MIN(INDEX(分野別!$J$5:$N$14,MATCH(A10,分野別!$A$5:$A$14,0),0)) -> 0 | E10: =MAX(INDEX(分野別!$J$5:$N$14,MATCH(A10,分野別!$A$5:$A$14,0),0)) -> 2 | F10: =AVERAGE(INDEX(分野別!$E$5:$N$14,MATCH(A10,分野別!$A$5:$A$14,0),0)) -> 1.4 | G10: 1
A11: 3 コンピュータ構成要素 | B11: ○ | C11: =AVERAGE(INDEX(分野別!$J$5:$N$14,MATCH(A11,分野別!$A$5:$A$14,0),0)) -> 1 | D11: =MIN(INDEX(分野別!$J$5:$N$14,MATCH(A11,分野別!$A$5:$A$14,0),0)) -> 1 | E11: =MAX(INDEX(分野別!$J$5:$N$14,MATCH(A11,分野別!$A$5:$A$14,0),0)) -> 1 | F11: =AVERAGE(INDEX(分野別!$E$5:$N$14,MATCH(A11,分野別!$A$5:$A$14,0),0)) -> 1.2 | G11: 1
A12: 17 システム戦略 | B12: ○ | C12: =AVERAGE(INDEX(分野別!$J$5:$N$14,MATCH(A12,分野別!$A$5:$A$14,0),0)) -> 1.2 | D12: =MIN(INDEX(分野別!$J$5:$N$14,MATCH(A12,分野別!$A$5:$A$14,0),0)) -> 0 | E12: =MAX(INDEX(分野別!$J$5:$N$14,MATCH(A12,分野別!$A$5:$A$14,0),0)) -> 2 | F12: =AVERAGE(INDEX(分野別!$E$5:$N$14,MATCH(A12,分野別!$A$5:$A$14,0),0)) -> 1.2 | G12: 1
A13: 10 ネットワーク | B13: ○ | C13: =AVERAGE(INDEX(分野別!$J$5:$N$14,MATCH(A13,分野別!$A$5:$A$14,0),0)) -> 1 | D13: =MIN(INDEX(分野別!$J$5:$N$14,MATCH(A13,分野別!$A$5:$A$14,0),0)) -> 1 | E13: =MAX(INDEX(分野別!$J$5:$N$14,MATCH(A13,分野別!$A$5:$A$14,0),0)) -> 1 | F13: =AVERAGE(INDEX(分野別!$E$5:$N$14,MATCH(A13,分野別!$A$5:$A$14,0),0)) -> 0.8 | G13: 1
A14: 7 ユーザーインタフェース | B14: ○ | C14: =AVERAGE(INDEX(分野別!$J$5:$N$14,MATCH(A14,分野別!$A$5:$A$14,0),0)) -> 0.4 | D14: =MIN(INDEX(分野別!$J$5:$N$14,MATCH(A14,分野別!$A$5:$A$14,0),0)) -> 0 | E14: =MAX(INDEX(分野別!$J$5:$N$14,MATCH(A14,分野別!$A$5:$A$14,0),0)) -> 1 | F14: =AVERAGE(INDEX(分野別!$E$5:$N$14,MATCH(A14,分野別!$A$5:$A$14,0),0)) -> 0.3 | G14: 1
A15: 合計 | G15: =SUM(G5:G14) -> 25

Sheet 用語一覧
A1: 覚えておきたい用語・テーマ(91件)
A2: 出題数・再出題・直近3回・最終出題・優先度は問題一覧からの数式。優先度Aは出題数5以上または直近3回で3以上、Bは出題数3以上または直近3回で2以上、それ以外はC。学習ポイントは出題内容をもとに整理した要点で、各問の解説ではありません。
A4: 優先度 | B4: 用語・テーマ | C4: 中分類 | D4: 出題数 | E4: 再出題あり | F4: 直近3回 | G4: 最終出題 | H4: 出題された年 | I4: 学習ポイント
A5: =IF(OR(D5>=5,F5>=3),"A",IF(OR(D5>=3,F5>=2),"B","C")) -> A | B5: デザインパターン/アーキテクチャパターン | C5: 12 システム開発技術 | D5: =COUNTIF(問題一覧!$D$5:$D$254,B5) -> 11 | E5: =COUNTIFS(問題一覧!$D$5:$D$254,B5,問題一覧!$E$5:$E$254,">=0") -> 7 | F5: =COUNTIFS(問題一覧!$D$5:$D$254,B5,問題一覧!$A$5:$A$254,">=2023") -> 4 | G5: =_xlfn.MAXIFS(問題一覧!$A$5:$A$254,問題一覧!$D$5:$D$254,B5) -> 2025 | H5: 2015・2017・2019・2022・2023・2024・2025 | I5: GoF23(生成: Singleton・Factory Method・Abstract Factory・Builder・Prototype / 構造: Adapter・Bridge・Composite・Decorator・Facade・Proxy / 振る舞い: Observer・Strategy・State・Template Method・Iterator・Command)、アーキテクチャパターン(MVC・レイヤー・パイプ&フィルタ・マイクロカーネル)
A6: =IF(OR(D6>=5,F6>=3),"A",IF(OR(D6>=3,F6>=2),"B","C")) -> A | B6: 電子署名・PKI・TPM | C6: 11 セキュリティ | D6: =COUNTIF(問題一覧!$D$5:$D$254,B6) -> 10 | E6: =COUNTIFS(問題一覧!$D$5:$D$254,B6,問題一覧!$E$5:$E$254,">=0") -> 7 | F6: =COUNTIFS(問題一覧!$D$5:$D$254,B6,問題一覧!$A$5:$A$254,">=2023") -> 5 | G6: =_xlfn.MAXIFS(問題一覧!$A$5:$A$254,問題一覧!$D$5:$D$254,B6) -> 2024 | H6: 2015・2017・2019・2021・2022・2023・2024 | I6: 署名の作成(秘密鍵)と検証(公開鍵)、ハッシュ値、認証局(CA)とディジタル証明書(X.509)、失効確認(CRL・OCSP)、タイムスタンプ、eシール、TPM(鍵保管チップ)、コード署名
A7: =IF(OR(D7>=5,F7>=3),"A",IF(OR(D7>=3,F7>=2),"B","C")) -> A | B7: JIS X 0160(SLCP) | C7: 12 システム開発技術 | D7: =COUNTIF(問題一覧!$D$5:$D$254,B7) -> 9 | E7: =COUNTIFS(問題一覧!$D$5:$D$254,B7,問題一覧!$E$5:$E$254,">=0") -> 0 | F7: =COUNTIFS(問題一覧!$D$5:$D$254,B7,問題一覧!$A$5:$A$254,">=2023") -> 3 | G7: =_xlfn.MAXIFS(問題一覧!$A$5:$A$254,問題一覧!$D$5:$D$254,B7) -> 2024 | H7: 2015・2016・2018・2019・2022・2023・2024 | I7: ソフトウェアライフサイクルプロセス(ISO/IEC/IEEE 12207)のプロセス群。テクニカルプロセスの各プロセス(要求事項定義・実装・統合・検証・移行・妥当性確認・運用・保守・廃棄)の目的とタスク。毎回違うプロセスが問われる
A8: =IF(OR(D8>=5,F8>=3),"A",IF(OR(D8>=3,F8>=2),"B","C")) -> A | B8: 要件定義・要求分析 | C8: 12 システム開発技術 | D8: =COUNTIF(問題一覧!$D$5:$D$254,B8) -> 7 | E8: =COUNTIFS(問題一覧!$D$5:$D$254,B8,問題一覧!$E$5:$E$254,">=0") -> 2 | F8: =COUNTIFS(問題一覧!$D$5:$D$254,B8,問題一覧!$A$5:$A$254,">=2023") -> 2 | G8: =_xlfn.MAXIFS(問題一覧!$A$5:$A$254,問題一覧!$D$5:$D$254,B8) -> 2025 | H8: 2017・2018・2021・2025 | I8: 機能要件と非機能要件、要求の抽出手法(構造化インタビュー・ワークショップ・観察・プロトタイピング)、ユースケース記述、BABOKの要求分類(ビジネス・ステークホルダ・ソリューション・移行)、検証と妥当性確認
A9: =IF(OR(D9>=5,F9>=3),"A",IF(OR(D9>=3,F9>=2),"B","C")) -> A | B9: 暗号方式 | C9: 11 セキュリティ | D9: =COUNTIF(問題一覧!$D$5:$D$254,B9) -> 7 | E9: =COUNTIFS(問題一覧!$D$5:$D$254,B9,問題一覧!$E$5:$E$254,">=0") -> 4 | F9: =COUNTIFS(問題一覧!$D$5:$D$254,B9,問題一覧!$A$5:$A$254,">=2023") -> 2 | G9: =_xlfn.MAXIFS(問題一覧!$A$5:$A$254,問題一覧!$D$5:$D$254,B9) -> 2024 | H9: 2016・2017・2019・2022・2023・2024 | I9: 共通鍵(AES・鍵長・ブロック暗号モード)と公開鍵(RSA・楕円曲線暗号)、ハイブリッド方式、CRYPTREC、WPA2(AES-CCMP)、ハッシュ関数(SHA-2・SHA-3)
A10: =IF(OR(D10>=5,F10>=3),"A",IF(OR(D10>=3,F10>=2),"B","C")) -> A | B10: 共通フレーム2013 | C10: 12 システム開発技術 | D10: =COUNTIF(問題一覧!$D$5:$D$254,B10) -> 7 | E10: =COUNTIFS(問題一覧!$D$5:$D$254,B10,問題一覧!$E$5:$E$254,">=0") -> 2 | F10: =COUNTIFS(問題一覧!$D$5:$D$254,B10,問題一覧!$A$5:$A$254,">=2023") -> 0 | G10: =_xlfn.MAXIFS(問題一覧!$A$5:$A$254,問題一覧!$D$5:$D$254,B10) -> 2021 | H10: 2015・2016・2018・2021 | I10: 企画・要件定義・開発・運用・保守の各プロセスとアクティビティ、システム適格性確認テスト、システム方式設計、取得者と供給者の責任。2022年以降は出題なし(JIS X 0160系へ移行)
A11: =IF(OR(D11>=5,F11>=3),"A",IF(OR(D11>=3,F11>=2),"B","C")) -> A | B11: 契約形態(請負/準委任/ラボ/実費償還) | C11: 18 システム企画 | D11: =COUNTIF(問題一覧!$D$5:$D$254,B11) -> 6 | E11: =COUNTIFS(問題一覧!$D$5:$D$254,B11,問題一覧!$E$5:$E$254,">=0") -> 5 | F11: =COUNTIFS(問題一覧!$D$5:$D$254,B11,問題一覧!$A$5:$A$254,">=2023") -> 2 | G11: =_xlfn.MAXIFS(問題一覧!$A$5:$A$254,問題一覧!$D$5:$D$254,B11) -> 2025 | H11: 2015・2016・2017・2022・2023・2025 | I11: 請負(完成責任)と準委任(善管注意義務)の違い、ラボ(ラボラトリ)型契約、実費償還型、定額契約、派遣との違い、情報システム・モデル取引・契約書の考え方
A12: =IF(OR(D12>=5,F12>=3),"A",IF(OR(D12>=3,F12>=2),"B","C")) -> A | B12: DFD/構造化技法 | C12: 12 システム開発技術 | D12: =COUNTIF(問題一覧!$D$5:$D$254,B12) -> 6 | E12: =COUNTIFS(問題一覧!$D$5:$D$254,B12,問題一覧!$E$5:$E$254,">=0") -> 2 | F12: =COUNTIFS(問題一覧!$D$5:$D$254,B12,問題一覧!$A$5:$A$254,">=2023") -> 2 | G12: =_xlfn.MAXIFS(問題一覧!$A$5:$A$254,問題一覧!$D$5:$D$254,B12) -> 2025 | H12: 2016・2019・2022・2023・2025 | I12: DFDの4要素(外部実体=源泉と吸収・プロセス・データフロー・データストア)、階層化とバランシング(親子のデータフロー整合)、デマルコの構造化技法、モジュール分割
A13: =IF(OR(D13>=5,F13>=3),"A",IF(OR(D13>=3,F13>=2),"B","C")) -> A | B13: プログラミング言語・アルゴリズム | C13: 12 システム開発技術 | D13: =COUNTIF(問題一覧!$D$5:$D$254,B13) -> 6 | E13: =COUNTIFS(問題一覧!$D$5:$D$254,B13,問題一覧!$E$5:$E$254,">=0") -> 2 | F13: =COUNTIFS(問題一覧!$D$5:$D$254,B13,問題一覧!$A$5:$A$254,">=2023") -> 3 | G13: =_xlfn.MAXIFS(問題一覧!$A$5:$A$254,問題一覧!$D$5:$D$254,B13) -> 2025 | H13: 2018・2019・2021・2024・2025 | I13: 引数の受渡し(値渡し・参照渡し・結果渡し)、関数型言語(参照透過性・純粋関数)、論理型言語(Prolog・ユニフィケーション)、流れ図のトレース
A14: =IF(OR(D14>=5,F14>=3),"A",IF(OR(D14>=3,F14>=2),"B","C")) -> A | B14: アジャイル/スクラム | C14: 13 ソフトウェア開発管理技術 | D14: =COUNTIF(問題一覧!$D$5:$D$254,B14) -> 6 | E14: =COUNTIFS(問題一覧!$D$5:$D$254,B14,問題一覧!$E$5:$E$254,">=0") -> 4 | F14: =COUNTIFS(問題一覧!$D$5:$D$254,B14,問題一覧!$A$5:$A$254,">=2023") -> 2 | G14: =_xlfn.MAXIFS(問題一覧!$A$5:$A$254,問題一覧!$D$5:$D$254,B14) -> 2024 | H14: 2017・2018・2019・2022・2023・2024 | I14: スクラムのイベント(プランニング・デイリー・レビュー・レトロスペクティブ)と役割(PO・SM・開発者)、成果物(プロダクトバックログ等)、INVEST(独立・交渉可能・価値・見積り可能・小さい・テスト可能)、KPT、インセプションデッキ、XP
A15: =IF(OR(D15>=5,F15>=3),"A",IF(OR(D15>=3,F15>=2),"B","C")) -> A | B15: テスト技法(ブラックボックス/網羅) | C15: 12 システム開発技術 | D15: =COUNTIF(問題一覧!$D$5:$D$254,B15) -> 6 | E15: =COUNTIFS(問題一覧!$D$5:$D$254,B15,問題一覧!$E$5:$E$254,">=0") -> 2 | F15: =COUNTIFS(問題一覧!$D$5:$D$254,B15,問題一覧!$A$5:$A$254,">=2023") -> 0 | G15: =_xlfn.MAXIFS(問題一覧!$A$5:$A$254,問題一覧!$D$5:$D$254,B15) -> 2021 | H15: 2015・2016・2018・2019・2021 | I15: 同値分割・境界値分析・デシジョンテーブル・状態遷移テスト・原因結果グラフ、ホワイトボックス(命令網羅・判定条件網羅・条件網羅・複数条件網羅)、実験計画法(直交表)
A16: =IF(OR(D16>=5,F16>=3),"A",IF(OR(D16>=3,F16>=2),"B","C")) -> A | B16: トランザクション制御 | C16: 9 データベース | D16: =COUNTIF(問題一覧!$D$5:$D$254,B16) -> 5 | E16: =COUNTIFS(問題一覧!$D$5:$D$254,B16,問題一覧!$E$5:$E$254,">=0") -> 0 | F16: =COUNTIFS(問題一覧!$D$5:$D$254,B16,問題一覧!$A$5:$A$254,">=2023") -> 3 | G16: =_xlfn.MAXIFS(問題一覧!$A$5:$A$254,問題一覧!$D$5:$D$254,B16) -> 2025 | H16: 2016・2022・2023・2024・2025 | I16: ACID特性、隔離性水準(READ COMMITTED等)とダーティリード・ノンリピータブルリード・ファントム、ロックとデッドロック(待ちグラフ)、コミットとロールバック、ログと障害回復。再出題はないが毎回出る
... A38: =IF(OR(D38>=5,F38>=3),"A",IF(OR(D38>=3,F38>=2),"B","C")) -> C | B38: 設計原則(SOLID) | C38: 12 システム開発技術 | D38: =COUNTIF(問題一覧!$D$5:$D$254,B38) -> 2 | E38: =COUNTIFS(問題一覧!$D$5:$D$254,B38,問題一覧!$E$5:$E$254,">=0") -> 2 | F38: =COUNTIFS(問題一覧!$D$5:$D$254,B38,問題一覧!$A$5:$A$254,">=2023") -> 1 | G38: =_xlfn.MAXIFS(問題一覧!$A$5:$A$254,問題一覧!$D$5:$D$254,B38) -> 2025 | H38: 2015・2025 | I38: 単一責任・開放閉鎖・リスコフの置換・インタフェース分離・依存関係逆転の5原則
A39: =IF(OR(D39>=5,F39>=3),"A",IF(OR(D39>=3,F39>=2),"B","C")) -> C | B39: MapReduce | C39: 4 システム構成要素 | D39: =COUNTIF(問題一覧!$D$5:$D$254,B39) -> 2 | E39: =COUNTIFS(問題一覧!$D$5:$D$254,B39,問題一覧!$E$5:$E$254,">=0") -> 2 | F39: =COUNTIFS(問題一覧!$D$5:$D$254,B39,問題一覧!$A$5:$A$254,">=2023") -> 1 | G39: =_xlfn.MAXIFS(問題一覧!$A$5:$A$254,問題一覧!$D$5:$D$254,B39) -> 2025 | H39: 2015・2025
A40: =IF(OR(D40>=5,F40>=3),"A",IF(OR(D40>=3,F40>=2),"B","C")) -> C | B40: カークパトリックモデル | C40: 12 システム開発技術 | D40: =COUNTIF(問題一覧!$D$5:$D$254,B40) -> 2 | E40: =COUNTIFS(問題一覧!$D$5:$D$254,B40,問題一覧!$E$5:$E$254,">=0") -> 2 | F40: =COUNTIFS(問題一覧!$D$5:$D$254,B40,問題一覧!$A$5:$A$254,">=2023") -> 1 | G40: =_xlfn.MAXIFS(問題一覧!$A$5:$A$254,問題一覧!$D$5:$D$254,B40) -> 2025 | H40: 2015・2025 | I40: 教育評価の4レベル(反応・学習・行動・成果)
A41: =IF(OR(D41>=5,F41>=3),"A",IF(OR(D41>=3,F41>=2),"B","C")) -> C | B41: DDoS/DNS攻撃 | C41: 11 セキュリティ | D41: =COUNTIF(問題一覧!$D$5:$D$254,B41) -> 2 | E41: =COUNTIFS(問題一覧!$D$5:$D$254,B41,問題一覧!$E$5:$E$254,">=0") -> 0 | F41: =COUNTIFS(問題一覧!$D$5:$D$254,B41,問題一覧!$A$5:$A$254,">=2023") -> 1 | G41: =_xlfn.MAXIFS(問題一覧!$A$5:$A$254,問題一覧!$D$5:$D$254,B41) -> 2025 | H41: 2022・2025 | I41: オープンリゾルバを悪用したDNS増幅(リフレクション)攻撃、マルチベクトル型DDoSの特徴と対策
A42: =IF(OR(D42>=5,F42>=3),"A",IF(OR(D42>=3,F42>=2),"B","C")) -> C | B42: キャッシュメモリ | C42: 3 コンピュータ構成要素 | D42: =COUNTIF(問題一覧!$D$5:$D$254,B42) -> 2 | E42: =COUNTIFS(問題一覧!$D$5:$D$254,B42,問題一覧!$E$5:$E$254,">=0") -> 0 | F42: =COUNTIFS(問題一覧!$D$5:$D$254,B42,問題一覧!$A$5:$A$254,">=2023") -> 1 | G42: =_xlfn.MAXIFS(問題一覧!$A$5:$A$254,問題一覧!$D$5:$D$254,B42) -> 2025 | H42: 2022・2025 | I42: ダイレクト・フルアソシアティブ・セットアソシアティブ、ヒット率と実効アクセス時間の計算、ライトスルーとライトバック
A43: =IF(OR(D43>=5,F43>=3),"A",IF(OR(D43>=3,F43>=2),"B","C")) -> B | B43: コンテナ/クラウド | C43: 4 システム構成要素 | D43: =COUNTIF(問題一覧!$D$5:$D$254,B43) -> 2 | E43: =COUNTIFS(問題一覧!$D$5:$D$254,B43,問題一覧!$E$5:$E$254,">=0") -> 0 | F43: =COUNTIFS(問題一覧!$D$5:$D$254,B43,問題一覧!$A$5:$A$254,">=2023") -> 2 | G43: =_xlfn.MAXIFS(問題一覧!$A$5:$A$254,問題一覧!$D$5:$D$254,B43) -> 2025 | H43: 2023・2025 | I43: コンテナ型仮想化とオーケストレーション(Kubernetes)、IaaS・PaaS・SaaS、クラウドサービス派生データ
A44: =IF(OR(D44>=5,F44>=3),"A",IF(OR(D44>=3,F44>=2),"B","C")) -> B | B44: 静的解析・複雑度 | C44: 12 システム開発技術 | D44: =COUNTIF(問題一覧!$D$5:$D$254,B44) -> 2 | E44: =COUNTIFS(問題一覧!$D$5:$D$254,B44,問題一覧!$E$5:$E$254,">=0") -> 0 | F44: =COUNTIFS(問題一覧!$D$5:$D$254,B44,問題一覧!$A$5:$A$254,">=2023") -> 2 | G44: =_xlfn.MAXIFS(問題一覧!$A$5:$A$254,問題一覧!$D$5:$D$254,B44) -> 2025 | H44: 2025
A45: =IF(OR(D45>=5,F45>=3),"A",IF(OR(D45>=3,F45>=2),"B","C")) -> C | B45: セキュリティ評価(CC/JISEC) | C45: 11 セキュリティ | D45: =COUNTIF(問題一覧!$D$5:$D$254,B45) -> 2 | E45: =COUNTIFS(問題一覧!$D$5:$D$254,B45,問題一覧!$E$5:$E$254,">=0") -> 0 | F45: =COUNTIFS(問題一覧!$D$5:$D$254,B45,問題一覧!$A$5:$A$254,">=2023") -> 1 | G45: =_xlfn.MAXIFS(問題一覧!$A$5:$A$254,問題一覧!$D$5:$D$254,B45) -> 2024 | H45: 2018・2024
A46: =IF(OR(D46>=5,F46>=3),"A",IF(OR(D46>=3,F46>=2),"B","C")) -> C | B46: アサーション | C46: 12 システム開発技術 | D46: =COUNTIF(問題一覧!$D$5:$D$254,B46) -> 2 | E46: =COUNTIFS(問題一覧!$D$5:$D$254,B46,問題一覧!$E$5:$E$254,">=0") -> 2 | F46: =COUNTIFS(問題一覧!$D$5:$D$254,B46,問題一覧!$A$5:$A$254,">=2023") -> 1 | G46: =_xlfn.MAXIFS(問題一覧!$A$5:$A$254,問題一覧!$D$5:$D$254,B46) -> 2024 | H46: 2019・2024
A47: =IF(OR(D47>=5,F47>=3),"A",IF(OR(D47>=3,F47>=2),"B","C")) -> C | B47: マイクロサービス | C47: 12 システム開発技術 | D47: =COUNTIF(問題一覧!$D$5:$D$254,B47) -> 2 | E47: =COUNTIFS(問題一覧!$D$5:$D$254,B47,問題一覧!$E$5:$E$254,">=0") -> 0 | F47: =COUNTIFS(問題一覧!$D$5:$D$254,B47,問題一覧!$A$5:$A$254,">=2023") -> 1 | G47: =_xlfn.MAXIFS(問題一覧!$A$5:$A$254,問題一覧!$D$5:$D$254,B47) -> 2024 | H47: 2021・2024 | I47: 小さなサービスをAPIで連携、独立したデプロイ、障害の局所化、サーキットブレーカ、APIゲートウェイ
A48: =IF(OR(D48>=5,F48>=3),"A",IF(OR(D48>=3,F48>=2),"B","C")) -> C | B48: 組込みでのDBMS | C48: 9 データベース | D48: =COUNTIF(問題一覧!$D$5:$D$254,B48) -> 2 | E48: =COUNTIFS(問題一覧!$D$5:$D$254,B48,問題一覧!$E$5:$E$254,">=0") -> 2 | F48: =COUNTIFS(問題一覧!$D$5:$D$254,B48,問題一覧!$A$5:$A$254,">=2023") -> 1 | G48: =_xlfn.MAXIFS(問題一覧!$A$5:$A$254,問題一覧!$D$5:$D$254,B48) -> 2024 | H48: 2022・2024
A49: =IF(OR(D49>=5,F49>=3),"A",IF(OR(D49>=3,F49>=2),"B","C")) -> C | B49: LSI設計 | C49: 12 システム開発技術 | D49: =COUNTIF(問題一覧!$D$5:$D$254,B49) -> 2 | E49: =COUNTIFS(問題一覧!$D$5:$D$254,B49,問題一覧!$E$5:$E$254,">=0") -> 2 | F49: =COUNTIFS(問題一覧!$D$5:$D$254,B49,問題一覧!$A$5:$A$254,">=2023") -> 1 | G49: =_xlfn.MAXIFS(問題一覧!$A$5:$A$254,問題一覧!$D$5:$D$254,B49) -> 2024 | H49: 2022・2024
A50: =IF(OR(D50>=5,F50>=3),"A",IF(OR(D50>=3,F50>=2),"B","C")) -> C | B50: 個人情報・プライバシー | C50: 11 セキュリティ | D50: =COUNTIF(問題一覧!$D$5:$D$254,B50) -> 2 | E50: =COUNTIFS(問題一覧!$D$5:$D$254,B50,問題一覧!$E$5:$E$254,">=0") -> 0 | F50: =COUNTIFS(問題一覧!$D$5:$D$254,B50,問題一覧!$A$5:$A$254,">=2023") -> 1 | G50: =_xlfn.MAXIFS(問題一覧!$A$5:$A$254,問題一覧!$D$5:$D$254,B50) -> 2023 | H50: 2016・2023
A51: =IF(OR(D51>=5,F51>=3),"A",IF(OR(D51>=3,F51>=2),"B","C")) -> C | B51: SoS(システムオブシステムズ) | C51: 12 システム開発技術 | D51: =COUNTIF(問題一覧!$D$5:$D$254,B51) -> 2 | E51: =COUNTIFS(問題一覧!$D$5:$D$254,B51,問題一覧!$E$5:$E$254,">=0") -> 2 | F51: =COUNTIFS(問題一覧!$D$5:$D$254,B51,問題一覧!$A$5:$A$254,">=2023") -> 1 | G51: =_xlfn.MAXIFS(問題一覧!$A$5:$A$254,問題一覧!$D$5:$D$254,B51) -> 2023 | H51: 2017・2023
A52: =IF(OR(D52>=5,F52>=3),"A",IF(OR(D52>=3,F52>=2),"B","C")) -> C | B52: ペアプログラミング | C52: 13 ソフトウェア開発管理技術 | D52: =COUNTIF(問題一覧!$D$5:$D$254,B52) -> 2 | E52: =COUNTIFS(問題一覧!$D$5:$D$254,B52,問題一覧!$E$5:$E$254,">=0") -> 0 | F52: =COUNTIFS(問題一覧!$D$5:$D$254,B52,問題一覧!$A$5:$A$254,">=2023") -> 1 | G52: =_xlfn.MAXIFS(問題一覧!$A$5:$A$254,問題一覧!$D$5:$D$254,B52) -> 2023 | H52: 2017・2023
A53: =IF(OR(D53>=5,F53>=3),"A",IF(OR(D53>=3,F53>=2),"B","C")) -> C | B53: RPC(リモート手続き呼出し) | C53: 4 システム構成要素 | D53: =COUNTIF(問題一覧!$D$5:$D$254,B53) -> 2 | E53: =COUNTIFS(問題一覧!$D$5:$D$254,B53,問題一覧!$E$5:$E$254,">=0") -> 2 | F53: =COUNTIFS(問題一覧!$D$5:$D$254,B53,問題一覧!$A$5:$A$254,">=2023") -> 1 | G53: =_xlfn.MAXIFS(問題一覧!$A$5:$A$254,問題一覧!$D$5:$D$254,B53) -> 2023 | H53: 2017・2023
A54: =IF(OR(D54>=5,F54>=3),"A",IF(OR(D54>=3,F54>=2),"B","C")) -> C | B54: Webアプリ設計(Servlet) | C54: 12 システム開発技術 | D54: =COUNTIF(問題一覧!$D$5:$D$254,B54) -> 2 | E54: =COUNTIFS(問題一覧!$D$5:$D$254,B54,問題一覧!$E$5:$E$254,">=0") -> 2 | F54: =COUNTIFS(問題一覧!$D$5:$D$254,B54,問題一覧!$A$5:$A$254,">=2023") -> 1 | G54: =_xlfn.MAXIFS(問題一覧!$A$5:$A$254,問題一覧!$D$5:$D$254,B54) -> 2023 | H54: 2019・2023
A55: =IF(OR(D55>=5,F55>=3),"A",IF(OR(D55>=3,F55>=2),"B","C")) -> C | B55: 探索的テスト | C55: 12 システム開発技術 | D55: =COUNTIF(問題一覧!$D$5:$D$254,B55) -> 2 | E55: =COUNTIFS(問題一覧!$D$5:$D$254,B55,問題一覧!$E$5:$E$254,">=0") -> 0 | F55: =COUNTIFS(問題一覧!$D$5:$D$254,B55,問題一覧!$A$5:$A$254,">=2023") -> 0 | G55: =_xlfn.MAXIFS(問題一覧!$A$5:$A$254,問題一覧!$D$5:$D$254,B55) -> 2022 | H55: 2017・2022 | I55: テスト設計と実行を同時に進め、結果から次のテストを決める手法
A56: =IF(OR(D56>=5,F56>=3),"A",IF(OR(D56>=3,F56>=2),"B","C")) -> C | B56: FMEA | C56: 12 システム開発技術 | D56: =COUNTIF(問題一覧!$D$5:$D$254,B56) -> 2 | E56: =COUNTIFS(問題一覧!$D$5:$D$254,B56,問題一覧!$E$5:$E$254,">=0") -> 2 | F56: =COUNTIFS(問題一覧!$D$5:$D$254,B56,問題一覧!$A$5:$A$254,">=2023") -> 0 | G56: =_xlfn.MAXIFS(問題一覧!$A$5:$A$254,問題一覧!$D$5:$D$254,B56) -> 2022 | H56: 2017・2022 | I56: 故障モード影響解析。設計段階で故障モードと影響を洗い出す予防的手法
A57: =IF(OR(D57>=5,F57>=3),"A",IF(OR(D57>=3,F57>=2),"B","C")) -> C | B57: イベント駆動・状態遷移 | C57: 12 システム開発技術 | D57: =COUNTIF(問題一覧!$D$5:$D$254,B57) -> 2 | E57: =COUNTIFS(問題一覧!$D$5:$D$254,B57,問題一覧!$E$5:$E$254,">=0") -> 2 | F57: =COUNTIFS(問題一覧!$D$5:$D$254,B57,問題一覧!$A$5:$A$254,">=2023") -> 0 | G57: =_xlfn.MAXIFS(問題一覧!$A$5:$A$254,問題一覧!$D$5:$D$254,B57) -> 2021 | H57: 2017・2021
A58: =IF(OR(D58>=5,F58>=3),"A",IF(OR(D58>=3,F58>=2),"B","C")) -> C | B58: 仮想記憶・割込み | C58: 3 コンピュータ構成要素 | D58: =COUNTIF(問題一覧!$D$5:$D$254,B58) -> 2 | E58: =COUNTIFS(問題一覧!$D$5:$D$254,B58,問題一覧!$E$5:$E$254,">=0") -> 0 | F58: =COUNTIFS(問題一覧!$D$5:$D$254,B58,問題一覧!$A$5:$A$254,">=2023") -> 0 | G58: =_xlfn.MAXIFS(問題一覧!$A$5:$A$254,問題一覧!$D$5:$D$254,B58) -> 2019 | H58: 2015・2019
A59: =IF(OR(D59>=5,F59>=3),"A",IF(OR(D59>=3,F59>=2),"B","C")) -> C | B59: ペトリネット(同期の要求モデル) | C59: 12 システム開発技術 | D59: =COUNTIF(問題一覧!$D$5:$D$254,B59) -> 2 | E59: =COUNTIFS(問題一覧!$D$5:$D$254,B59,問題一覧!$E$5:$E$254,">=0") -> 2 | F59: =COUNTIFS(問題一覧!$D$5:$D$254,B59,問題一覧!$A$5:$A$254,">=2023") -> 0 | G59: =_xlfn.MAXIFS(問題一覧!$A$5:$A$254,問題一覧!$D$5:$D$254,B59) -> 2019 | H59: 2016・2019
A60: =IF(OR(D60>=5,F60>=3),"A",IF(OR(D60>=3,F60>=2),"B","C")) -> C | B60: 関係モデル・正規化 | C60: 9 データベース | D60: =COUNTIF(問題一覧!$D$5:$D$254,B60) -> 2 | E60: =COUNTIFS(問題一覧!$D$5:$D$254,B60,問題一覧!$E$5:$E$254,">=0") -> 0 | F60: =COUNTIFS(問題一覧!$D$5:$D$254,B60,問題一覧!$A$5:$A$254,">=2023") -> 0 | G60: =_xlfn.MAXIFS(問題一覧!$A$5:$A$254,問題一覧!$D$5:$D$254,B60) -> 2019 | H60: 2018・2019
A61: =IF(OR(D61>=5,F61>=3),"A",IF(OR(D61>=3,F61>=2),"B","C")) -> C | B61: 検査費用の計算 | C61: 12 システム開発技術 | D61: =COUNTIF(問題一覧!$D$5:$D$254,B61) -> 2 | E61: =COUNTIFS(問題一覧!$D$5:$D$254,B61,問題一覧!$E$5:$E$254,">=0") -> 2 | F61: =COUNTIFS(問題一覧!$D$5:$D$254,B61,問題一覧!$A$5:$A$254,">=2023") -> 0 | G61: =_xlfn.MAXIFS(問題一覧!$A$5:$A$254,問題一覧!$D$5:$D$254,B61) -> 2018 | H61: 2015・2018
A62: =IF(OR(D62>=5,F62>=3),"A",IF(OR(D62>=3,F62>=2),"B","C")) -> C | B62: 再利用(ドメイン工学) | C62: 13 ソフトウェア開発管理技術 | D62: =COUNTIF(問題一覧!$D$5:$D$254,B62) -> 2 | E62: =COUNTIFS(問題一覧!$D$5:$D$254,B62,問題一覧!$E$5:$E$254,">=0") -> 2 | F62: =COUNTIFS(問題一覧!$D$5:$D$254,B62,問題一覧!$A$5:$A$254,">=2023") -> 0 | G62: =_xlfn.MAXIFS(問題一覧!$A$5:$A$254,問題一覧!$D$5:$D$254,B62) -> 2017 | H62: 2015・2017
...

Sheet 回別内訳
A1: 回ごとの再出題の内訳
A2: 類似度判定の結果(固定値)。最初の数回は比べる過去問が少ないため、過去に同一問題ありが小さく出ます。
A4: 年 | B4: 過去に同一問題あり | C4: 初出(後年に再出題) | D4: 同テーマの別設問のみ | E4: 単発 | F4: 合計
A5: 2015 | B5: 0 | C5: 10 | D5: 12 | E5: 3 | F5: =SUM(B5:E5) -> 25
A6: 2016 | B6: 0 | C6: 3 | D6: 18 | E6: 4 | F6: =SUM(B6:E6) -> 25
A7: 2017 | B7: 2 | C7: 11 | D7: 10 | E7: 2 | F7: =SUM(B7:E7) -> 25
A8: 2018 | B8: 3 | C8: 5 | D8: 14 | E8: 3 | F8: =SUM(B8:E8) -> 25
A9: 2019 | B9: 5 | C9: 6 | D9: 11 | E9: 3 | F9: =SUM(B9:E9) -> 25
A10: 2021 | B10: 6 | C10: 4 | D10: 11 | E10: 4 | F10: =SUM(B10:E10) -> 25
A11: 2022 | B11: 5 | C11: 5 | D11: 13 | E11: 2 | F11: =SUM(B11:E11) -> 25
A12: 2023 | B12: 11 | C12: 1 | D12: 12 | E12: 1 | F12: =SUM(B12:E12) -> 25
A13: 2024 | B13: 10 | C13: 0 | D13: 13 | E13: 2 | F13: =SUM(B13:E13) -> 25
A14: 2025 | B14: 9 | C14: 0 | D14: 9 | E14: 7 | F14: =SUM(B14:E14) -> 25

Sheet 再出題の間隔
A1: 同一問題は何回後に再出題されたか
A2: 実施された回の数で数えています(試験がない年は飛ばす)。0は翌回に再出題された例がないことを表します。
A4: 間隔(回後) | B4: 組数
A5: 1 | B5: 0
A6: 2 | B6: 20
A7: 3 | B7: 11
A8: 4 | B8: 8
A9: 5 | B9: 4
A10: 6 | B10: 3
A11: 7 | B11: 0
A12: 8 | B12: 2
A13: 9 | B13: 3
A14: 合計 | B14: =SUM(B5:B13) -> 51

Sheet 回どうしの重なり
A1: 2つの回の組ごとの同一問題の数
A2: 行の回の問題のうち、列の回にも同一問題がある数。連続する2回(斜め隣)はすべて0です。
A4: 年 | B4: 2015 | C4: 2016 | D4: 2017 | E4: 2018 | F4: 2019 | G4: 2021 | H4: 2022 | I4: 2023 | J4: 2024 | K4: 2025
A5: 2015 | C5: 0 | D5: 2 | E5: 2 | F5: 0 | G5: 1 | H5: 1 | I5: 1 | J5: 1 | K5: 3
A6: 2016 | B6: 0 | D6: 0 | E6: 1 | F6: 1 | G6: 0 | H6: 0 | I6: 0 | J6: 0 | K6: 1
A7: 2017 | B7: 2 | C7: 0 | E7: 0 | F7: 4 | G7: 2 | H7: 3 | I7: 3 | J7: 3 | K7: 1
A8: 2018 | B8: 2 | C8: 1 | D8: 0 | F8: 0 | G8: 3 | H8: 0 | I8: 3 | J8: 0 | K8: 0
A9: 2019 | B9: 0 | C9: 1 | D9: 4 | E9: 0 | G9: 0 | H9: 3 | I9: 4 | J9: 2 | K9: 0
A10: 2021 | B10: 1 | C10: 0 | D10: 2 | E10: 3 | F10: 0 | H10: 0 | I10: 2 | J10: 1 | K10: 3
A11: 2022 | B11: 1 | C11: 0 | D11: 3 | E11: 0 | F11: 3 | G11: 0 | I11: 0 | J11: 4 | K11: 1
A12: 2023 | B12: 1 | C12: 0 | D12: 3 | E12: 3 | F12: 4 | G12: 2 | H12: 0 | J12: 0 | K12: 1
A13: 2024 | B13: 1 | C13: 0 | D13: 3 | E13: 0 | F13: 2 | G13: 1 | H13: 4 | I13: 0 | K13: 0
A14: 2025 | B14: 3 | C14: 1 | D14: 1 | E14: 0 | F14: 0 | G14: 3 | H14: 1 | I14: 1 | J14: 0

Sheet 過去問のカバー数
A1: 直前N回分の過去問でカバーできる平均問数
A2: 2021〜2025の各回について、直前N回分に載っていた問題数の平均(固定値)。同テーマは同じ用語分類の問題を含みます。
A4: 直前の回数 | B4: 同一問題 | C4: 同一問題+同テーマ
A5: 1 | B5: 0 | C5: 6
A6: 2 | B6: 2.6 | C6: 12.8
A7: 3 | B7: 4.2 | C7: 15.8
A8: 4 | B8: 5.8 | C8: 17
A9: 5 | B9: 6.6 | C9: 18.2
